Workbook

Sheet Léame
A1: BOMAG Compare Hub — Matriz de datos y análisis financiero
A2: Exportado desde el código fuente de la aplicación (src/data/*, src/utils/financialFields.ts, src/utils/productLineFinancial.ts, src/components/MachineComparison.tsx, ArticulationJointCostAnalysis.tsx).
A4: Convención de colores
A5: Texto azul | B5: Dato de entrada / supuesto editable (valor fijo tomado de la app).
A6: Texto negro | B6: Fórmula calculada — no sobrescribir.
A7: Texto verde | B7: Vínculo a otra hoja (p. ej. precio y consumo tomados de la hoja de datos).
A8: Relleno amarillo | B8: Supuestos clave globales (hoja Supuestos) y selectores del Comparador.
A10: Hojas
A11: Supuestos | B11: Parámetros globales: precio del diésel, horas de operación, eficiencia, volumen, tipo de suelo, junta articulada, parámetros de pavimentadoras y fresadoras, tasas de cambio.
A12: Datos SDR / LTR / HTR | B12: Matriz completa de especificaciones de rodillos (textos en español). Precio, consumo y mantenimiento alimentan los análisis.
A13: Datos Fresadoras | B13: Especificaciones y variables financieras de fresadoras en frío.
A14: Datos Pavimentadoras | B14: Especificaciones y bloque financiero (consumo, CO₂, calentamiento, reemplazos de plancha).
A15: Análisis Compactación | B15: TCO por máquina (SDR+LTR+HTR): combustible, mantenimiento, junta articulada, rendimiento y costo por volumen.
A16: Análisis Fresadoras | B16: TCO con BMS15L (reducción de desgaste), desgaste de herramientas y horas de trabajo por volumen.
A17: Análisis Pavimentadoras | B17: TCO con ECOMODE / modos de ahorro, MAGMALIFE (combustible de calentamiento y desgaste de plancha).
A18: Junta Articulada | B18: Análisis de costo de engrase: competidor vs BOMAG.
A19: TCO Progresivo | B19: TCO acumulado a 0…10.000 h por máquina (todas las líneas).
A20: Comparador | B20: Elija hasta 4 máquinas de compactación (lista desplegable) para verlas lado a lado, como en la app.
A21: Tablas Rendimiento | B21: Tablas de rendimiento y altura de capa por peso y tipo de suelo.
A22: Mant. BM 1000-20 | B22: Rutina y costos de mantenimiento preventivo de la fresadora BM 1000/20.
... A29: Monedas | B29: Todos los montos se guardan en USD (igual que la app). La columna "TCO (moneda sel.)" convierte con la tasa elegida en Supuestos.
A31: Notas importantes
A32: Rendimiento base | B32: La app calcula el rendimiento con una interpolación por peso (correctedPerformanceData.ts). Los 4 valores por suelo se exportaron tal cual (azul) y la fórmula elige el del suelo seleccionado.
A33: Desgaste de plancha | B33: En la app, "~24.000 €" se interpreta como 24 € (el punto de miles se lee como decimal), dando ~$0,009/h. Este Excel usa el importe correcto (24.000 € → $8,64/h). Puede cambiar el monto en la hoja Análisis Pavimentadoras.
A34: Precios en 0 | B34: Fresadoras y pavimentadoras no tienen precio cargado en la app (0). Ingréselos en azul para obtener un TCO completo.

Sheet Supuestos
A1: Supuestos globales
A3: Parámetro | B3: Valor | C3: Unidad | D3: Fuente / nota
A4: Operación (todas las líneas)
A5: Precio del diésel | B5: 1.2 | C5: USD/L | D5: Valor por defecto de la app (fuelPriceUSD).
A6: Tiempo de operación a analizar | B6: 3000 | C6: h | D6: Valor por defecto de la app (operationTimeHours).
A7: Compactación (SDR / LTR / HTR)
A8: Tipo de suelo seleccionado | B8: Suelo mixto | D8: Roca / Grava / Suelo mixto / Arcilla. Por defecto en la app: suelo mixto.
A9: Eficiencia de trabajo | B9: 1 | C9: % | D9: workEfficiency (0–100 %). Por defecto 100 %.
A10: Volumen a compactar | B10: 0 | C10: m³ | D10: Ingrese el volumen (Largo × Ancho × Alto) para calcular horas y costo del trabajo.
A11: Multiplicador tecnología BOMAG (Economizer/Terrameter) | B11: 1.25 | C11: x | D11: Se aplica al rendimiento solo si la máquina es BOMAG y la tecnología está activa.
A12: Junta articulada (solo SDR)
A13: Tarifa técnico | B13: 35 | C13: USD/h | D13: aj_technicianRate
A14: Costo máquina parada | B14: 120 | C14: USD/h | D14: aj_machineIdleRate
A15: Costo de grasa por intervención | B15: 15 | C15: USD | D15: aj_greaseCostPerIntervention
A16: Intervalo de engrase del competidor | B16: 50 | C16: h | D16: Tabla BOMAG: cada 50 h (o semanal).
A17: Tiempo por engrase | B17: 0.5 | C17: h | D17: Tabla BOMAG: 30 minutos.
A18: Fresadoras
A19: Volumen a fresar | B19: 0 | C19: m³ | D19: millingVolumeM3
A20: Reducción de desgaste BMS15L (por defecto) | B20: 0.2 | C20: % | D20: MILLING_BMS15L_WEAR_REDUCTION
A21: Pavimentadoras
A22: Tipo de cambio EUR → USD (datos en €) | B22: 1.08 | C22: USD/EUR | D22: EUR_TO_USD en financialFields.ts
A23: Horas por turno | B23: 10 | C23: h | D23: PAVER_HOURS_PER_SHIFT
A24: Ahorro de combustible ECOMODE (BOMAG) | B24: 0.17 | C24: % | D24: PAVER_ECOMODE_FUEL_SAVINGS
A25: Factor consumo EcoPlus (Vögele) | B25: 0.75 | C25: x | D25: productLineFinancial.ts
A26: Factor consumo VarioSpeed (Dynapac) | B26: 0.9 | C26: x | D26: productLineFinancial.ts
A27: Factor consumo Eco-mode (Caterpillar) | B27: 0.9 | C27: x | D27: productLineFinancial.ts
A28: Combustible de calentamiento competidor | B28: 10.5 | C28: L/turno | D28: PAVER_COMPETITOR_SETUP_FUEL_L
A29: Combustible de calentamiento MAGMALIFE | B29: 3.5 | C29: L/turno | D29: PAVER_MAGMALIFE_SETUP_FUEL_L
A30: Reemplazos de plancha competidor (3 años) | B30: 24000 | C30: EUR | D30: PAVER_COMPETITOR_WEAR_3Y_EUR (~24.000 €)
A31: Horas de operación por año (plancha) | B31: 1000 | C31: h/año | D31: PAVER_WEAR_HOURS_PER_YEAR
A32: Minutos de calentamiento sin MAGMALIFE | B32: 60 | C32: min | D32: Valor por defecto de la app
A34: Monedas (unidades por 1 USD)
A35: Moneda | B35: Tasa por USD | D35: Nota
A36: USD | B36: 1 | D36: Tasas de respaldo de la app (CurrencyContext.tsx). La app las actualiza en línea; edítelas aquí.
A37: EUR | B37: 0.92
A38: IDR | B38: 16500
A39: KRW | B39: 1380
A40: THB | B40: 33.5
A41: VND | B41: 25500
A42: MYR | B42: 4.45
...

Sheet Datos SDR
A1: ID | B1: Marca | C1: Modelo | D1: N.º material | E1: Peso (kg) | F1: Motor | G1: Ancho de compactación (m) | H1: Potencia (HP) | I1: Amplitud (mm) | J1: Carga lineal estática (kg/cm) | K1: Gradeabilidad (%) | L1: País de origen | M1: Asistente de compactación | N1: Telemetría | O1: Tecnologías innovadoras | P1: USP | Q1: USP 1 | R1: USP 2 | S1: USP 3 | T1: USP 4 | U1: USP 5 | V1: USP 6 | W1: Profundidad de compactación máx. | X1: Rendimiento en compactación (m³/h, ficha) | Y1: Consumo de combustible (L/h) | Z1: Precio CIF (USD) | AA1: Mant. preventivo (USD/h) | AB1: Mant. correctivo (USD/h) | AC1: Tiempo de uso (h) | AD1: TCO estático app (USD) | AE1: Línea de tiempo TCO (datos app)
A2: =B2&" | "&C2 -> BOMAG | BW211 D-5 SL | B2: BOMAG | C2: BW211 D-5 SL | D2: 93500000 | E2: 10630 | F2: Cummins 4BT 3.9 | G2: 2.1 | H2: 100 | I2: 1.80 / 0.95 | J2: 28.4 | K2: 45 | L2: India | M2: BOMAG ECONOMIZER Sistema visual que permite a los operadores medir el progreso de la compactación en tiempo real. Utiliza una escala LED en la cabina para mostrar el nivel de compactación alcanzado, ayudando a evitar sobrecompacción o subcompactación. (Estandar) BOMAG TERRAMETER Sistema que mide la rigidez del suelo mediante la vibración del tambor. Ofrece una lectura en tiempo real del módulo de elasticidad del material compactado, lo que facilita el control preciso de la compactación y la trazabilidad de los trabajos. Evib - MN/m2 | N2: Telematics | O2: Economizer, TERRAMETER (Evib real), VARIOCONTROL, ECOMODE, TELEMATIC | Q2: Operación Intuitiva * Un switch para cada función * Símbolos intuitivos facilitan la operación | R2: Rendimiento de compactación más alto * Máximas amplitudes para un efecto de compactación más profundo (Larger amplitud 2,2 mm) * Flexibilidad en el montaje del kit pata de cabra | S2: Junta de articulación libre de mantenimiento | T2: Trabajo comfortable y seguro * Espacio de trabajo amplio y con excelente visibilidad | U2: Compactación eficiente Medición y documentación en tiempo real usando: ECONOMIZER, TERRAMETER y BOMAP | V2: Fácil mantenimiento * Todos los componentes dispuestos para un fácil acceso * Menos mantenimiento en el sistema de refrigeración debido al el punto alto de entrada de aire, menos propenso a contaminación | W2: 60 | X2: 270 - 540 | Y2: 11.8 | Z2: 57592.78 | AA2: 1 | AB2: 2 | AC2: 3000 | AD2: 109072.78 | AE2: 1000 h: precio 42800 / TCO 109072.78; 1500 h: precio 50200 / TCO 109072.78; 2000 h: precio 57600 / TCO 109072.78; 2500 h: precio 65000 / TCO 109072.78; 3000 h: precio 72400 / TCO 109072.78
A3: =B3&" | "&C3 -> BOMAG | BW211 D-5 SL | B3: BOMAG | C3: BW211 D-5 SL | D3: 93500004 | E3: 10630 | F3: Cummins 4BTAA 3.9 | G3: 2.1 | H3: 110 | I3: 1.80 / 0.95 | J3: 28.4 | K3: 45 | L3: India | M3: BOMAG ECONOMIZER Sistema visual que permite a los operadores medir el progreso de la compactación en tiempo real. Utiliza una escala LED en la cabina para mostrar el nivel de compactación alcanzado, ayudando a evitar sobrecompacción o subcompactación. (Estandar) BOMAG TERRAMETER Sistema que mide la rigidez del suelo mediante la vibración del tambor. Ofrece una lectura en tiempo real del módulo de elasticidad del material compactado, lo que facilita el control preciso de la compactación y la trazabilidad de los trabajos. Evib - MN/m2 | N3: Telematics | O3: Economizer, TERRAMETER (Evib real), VARIOCONTROL, ECOMODE, TELEMATIC | Q3: Operación Intuitiva * Un switch para cada función * Símbolos intuitivos facilitan la operación | R3: Rendimiento de compactación más alto * Máximas amplitudes para un efecto de compactación más profundo (Larger amplitud 2,2 mm) * Flexibilidad en el montaje del kit pata de cabra | S3: Junta de articulación libre de mantenimiento | T3: Trabajo comfortable y seguro * Espacio de trabajo amplio y con excelente visibilidad | U3: Compactación eficiente Medición y documentación en tiempo real usando: ECONOMIZER, TERRAMETER y BOMAP | V3: Fácil mantenimiento * Todos los componentes dispuestos para un fácil acceso * Menos mantenimiento en el sistema de refrigeración debido al el punto alto de entrada de aire, menos propenso a contaminación | W3: 60 | X3: 270 - 540 | Y3: 11.8 | Z3: 59374 | AA3: 1 | AB3: 2 | AC3: 3000 | AD3: 110854 | AE3: 1000 h: precio 44430 / TCO 110854; 1500 h: precio 51830 / TCO 110854; 2000 h: precio 59230 / TCO 110854; 2500 h: precio 66630 / TCO 110854; 3000 h: precio 74030 / TCO 110854
A4: =B4&" | "&C4 -> BOMAG | BW211 D-5 SL | B4: BOMAG | C4: BW211 D-5 SL | D4: 58400031 | E4: 10630 | F4: Deutz BF4M 2012 C | G4: 2.1 | H4: 132 | I4: 1.80 / 0.95 | J4: 28.4 | K4: 45 | L4: China | M4: BOMAG ECONOMIZER Sistema visual que permite a los operadores medir el progreso de la compactación en tiempo real. Utiliza una escala LED en la cabina para mostrar el nivel de compactación alcanzado, ayudando a evitar sobrecompacción o subcompactación. (Estandar) BOMAG TERRAMETER Sistema que mide la rigidez del suelo mediante la vibración del tambor. Ofrece una lectura en tiempo real del módulo de elasticidad del material compactado, lo que facilita el control preciso de la compactación y la trazabilidad de los trabajos. Evib - MN/m2 | N4: Telematics | O4: Economizer, TERRAMETER (Evib real), VARIOCONTROL, ECOMODE, TELEMATIC | Q4: Operación Intuitiva * Un switch para cada función * Símbolos intuitivos facilitan la operación | R4: Rendimiento de compactación más alto * Máximas amplitudes para un efecto de compactación más profundo (Larger amplitud 2,2 mm) * Flexibilidad en el montaje del kit pata de cabra | S4: Junta de articulación libre de mantenimiento | T4: Trabajo comfortable y seguro * Espacio de trabajo amplio y con excelente visibilidad | U4: Compactación eficiente Medición y documentación en tiempo real usando: ECONOMIZER, TERRAMETER y BOMAP | V4: Fácil mantenimiento * Todos los componentes dispuestos para un fácil acceso * Menos mantenimiento en el sistema de refrigeración debido al el punto alto de entrada de aire, menos propenso a contaminación | W4: 60 | X4: 270 - 540 | Y4: 12.4 | Z4: 63530.18 | AA4: 1 | AB4: 2 | AC4: 3000 | AD4: 117170.18 | AE4: 1000 h: precio 44980 / TCO 117170.18; 1500 h: precio 52680 / TCO 117170.18; 2000 h: precio 60380 / TCO 117170.18; 2500 h: precio 68080 / TCO 117170.18; 3000 h: precio 75780 / TCO 117170.18
A5: =B5&" | "&C5 -> BOMAG | BW211 D-5 SL | B5: BOMAG | C5: BW211 D-5 SL | D5: 58400033 | E5: 10630 | F5: Deutz TCD 2012 L04 2V | G5: 2.13 | H5: 140 | I5: 1.80 / 0.96 | J5: 26.8 | K5: 45 | L5: China | M5: BOMAG ECONOMIZER Sistema visual que permite a los operadores medir el progreso de la compactación en tiempo real. Utiliza una escala LED en la cabina para mostrar el nivel de compactación alcanzado, ayudando a evitar sobrecompacción o subcompactación. (Estandar) BOMAG TERRAMETER Sistema que mide la rigidez del suelo mediante la vibración del tambor. Ofrece una lectura en tiempo real del módulo de elasticidad del material compactado, lo que facilita el control preciso de la compactación y la trazabilidad de los trabajos. Evib - MN/m2 | N5: Telematics | O5: Economizer, TERRAMETER (Evib real), VARIOCONTROL, ECOMODE, TELEMATIC | Q5: Operación Intuitiva * Un switch para cada función * Símbolos intuitivos facilitan la operación | R5: Rendimiento de compactación más alto * Máximas amplitudes para un efecto de compactación más profundo (Larger amplitud 2,2 mm) * Flexibilidad en el montaje del kit pata de cabra | S5: Junta de articulación libre de mantenimiento | T5: Trabajo comfortable y seguro * Espacio de trabajo amplio y con excelente visibilidad | U5: Compactación eficiente Medición y documentación en tiempo real usando: ECONOMIZER, TERRAMETER y BOMAP | V5: Fácil mantenimiento * Todos los componentes dispuestos para un fácil acceso * Menos mantenimiento en el sistema de refrigeración debido al el punto alto de entrada de aire, menos propenso a contaminación | W5: 60 | X5: 270 - 540 | Y5: 12.4 | Z5: 66500 | AA5: 1 | AB5: 2 | AC5: 3000 | AD5: 120140 | AE5: 1000 h: precio 44980 / TCO 120140; 1500 h: precio 52680 / TCO 120140; 2000 h: precio 60380 / TCO 120140; 2500 h: precio 68080 / TCO 120140; 3000 h: precio 75780 / TCO 120140
A6: =B6&" | "&C6 -> BOMAG | BW212 D-5 SL | B6: BOMAG | C6: BW212 D-5 SL | D6: 58400036 | E6: 11490 | F6: Deutz BF4M 2012 C | G6: 2.13 | H6: 132 | I6: 1.80 / 0.96 | J6: 32.4 | K6: 45 | L6: China | M6: BOMAG ECONOMIZER Sistema visual que permite a los operadores medir el progreso de la compactación en tiempo real. Utiliza una escala LED en la cabina para mostrar el nivel de compactación alcanzado, ayudando a evitar sobrecompacción o subcompactación. (Estandar) BOMAG TERRAMETER Sistema que mide la rigidez del suelo mediante la vibración del tambor. Ofrece una lectura en tiempo real del módulo de elasticidad del material compactado, lo que facilita el control preciso de la compactación y la trazabilidad de los trabajos. Evib - MN/m2 | N6: Telematics | O6: Economizer, TERRAMETER (Evib real), VARIOCONTROL, ECOMODE, TELEMATIC | Q6: Operación Intuitiva * Un switch para cada función * Símbolos intuitivos facilitan la operación | R6: Rendimiento de compactación más alto * Máximas amplitudes para un efecto de compactación más profundo (Larger amplitud 2,2 mm) * Flexibilidad en el montaje del kit pata de cabra | S6: Junta de articulación libre de mantenimiento | T6: Trabajo comfortable y seguro * Espacio de trabajo amplio y con excelente visibilidad | U6: Compactación eficiente Medición y documentación en tiempo real usando: ECONOMIZER, TERRAMETER y BOMAP | V6: Fácil mantenimiento * Todos los componentes dispuestos para un fácil acceso * Menos mantenimiento en el sistema de refrigeración debido al el punto alto de entrada de aire, menos propenso a contaminación | W6: 60 | X6: 270 - 540 | Y6: 12.4 | Z6: 68684 | AA6: 1 | AB6: 2 | AC6: 3000 | AD6: 122324 | AE6: 1000 h: precio 688700 / TCO 122324; 1500 h: precio 802660 / TCO 122324; 2000 h: precio 916620 / TCO 122324; 2500 h: precio 1030580 / TCO 122324; 3000 h: precio 1144540 / TCO 122324
A7: =B7&" | "&C7 -> BOMAG | BW213 D-5 SL | B7: BOMAG | C7: BW213 D-5 SL | D7: 58400041 | E7: 12320 | F7: Deutz BF4M 2012 C | G7: 2.13 | H7: 132 | I7: 1.80 / 0.96 | J7: 37.1 | K7: 45 | L7: China | M7: BOMAG ECONOMIZER Sistema visual que permite a los operadores medir el progreso de la compactación en tiempo real. Utiliza una escala LED en la cabina para mostrar el nivel de compactación alcanzado, ayudando a evitar sobrecompacción o subcompactación. (Estandar) BOMAG TERRAMETER Sistema que mide la rigidez del suelo mediante la vibración del tambor. Ofrece una lectura en tiempo real del módulo de elasticidad del material compactado, lo que facilita el control preciso de la compactación y la trazabilidad de los trabajos. Evib - MN/m2 | N7: Telematics | O7: Economizer, TERRAMETER (Evib real), VARIOCONTROL, ECOMODE, TELEMATIC | Q7: Operación Intuitiva * Un switch para cada función * Símbolos intuitivos facilitan la operación | R7: Rendimiento de compactación más alto * Máximas amplitudes para un efecto de compactación más profundo (Larger amplitud 2,2 mm) * Flexibilidad en el montaje del kit pata de cabra | S7: Junta de articulación libre de mantenimiento | T7: Trabajo comfortable y seguro * Espacio de trabajo amplio y con excelente visibilidad | U7: Compactación eficiente Medición y documentación en tiempo real usando: ECONOMIZER, TERRAMETER y BOMAP | V7: Fácil mantenimiento * Todos los componentes dispuestos para un fácil acceso * Menos mantenimiento en el sistema de refrigeración debido al el punto alto de entrada de aire, menos propenso a contaminación | W7: 60 | X7: 270 - 540 | Y7: 12.4 | Z7: 72948 | AA7: 1 | AB7: 2 | AC7: 3000 | AD7: 126588 | AE7: 1000 h: precio 713802 / TCO 126588; 1500 h: precio 827762 / TCO 126588; 2000 h: precio 941722 / TCO 126588; 2500 h: precio 1055682 / TCO 126588; 3000 h: precio 1169642 / TCO 126588
A8: =B8&" | "&C8 -> BOMAG | BW213 D-5 SL TCD | B8: BOMAG | C8: BW213 D-5 SL TCD | D8: 58400041 | E8: 11960 | F8: Deutz TCD 2021 L04 2V | G8: 2.13 | H8: 140 | I8: 1.90 / 0.96 | J8: 37 | K8: 45 | L8: China | M8: BOMAG ECONOMIZER Sistema visual que permite a los operadores medir el progreso de la compactación en tiempo real. Utiliza una escala LED en la cabina para mostrar el nivel de compactación alcanzado, ayudando a evitar sobrecompacción o subcompactación. (Estandar) BOMAG TERRAMETER Sistema que mide la rigidez del suelo mediante la vibración del tambor. Ofrece una lectura en tiempo real del módulo de elasticidad del material compactado, lo que facilita el control preciso de la compactación y la trazabilidad de los trabajos. Evib - MN/m2 | N8: Telematics | O8: Economizer, TERRAMETER (Evib real), VARIOCONTROL, ECOMODE, TELEMATIC | Q8: Operación Intuitiva * Un switch para cada función * Símbolos intuitivos facilitan la operación | R8: Rendimiento de compactación más alto * Máximas amplitudes para un efecto de compactación más profundo (Larger amplitud 2,2 mm) * Flexibilidad en el montaje del kit pata de cabra | S8: Junta de articulación libre de mantenimiento | T8: Trabajo comfortable y seguro * Espacio de trabajo amplio y con excelente visibilidad | U8: Compactación eficiente Medición y documentación en tiempo real usando: ECONOMIZER, TERRAMETER y BOMAP | V8: Fácil mantenimiento * Todos los componentes dispuestos para un fácil acceso * Menos mantenimiento en el sistema de refrigeración debido al el punto alto de entrada de aire, menos propenso a contaminación | W8: 60 | X8: 270 - 540 | Y8: 12.4 | Z8: 72948 | AA8: 1 | AB8: 2 | AC8: 3000 | AD8: 126588
A9: =B9&" | "&C9 -> BOMAG | BW216 D-5 SL | B9: BOMAG | C9: BW216 D-5 SL | E9: 14850 | F9: Deutz TCD 2013 L04 | G9: 2.13 | H9: 162 | I9: 1.90 / 0.96 | J9: 50.2 | L9: - | M9: BOMAG ECONOMIZER Sistema visual que permite a los operadores medir el progreso de la compactación en tiempo real. Utiliza una escala LED en la cabina para mostrar el nivel de compactación alcanzado, ayudando a evitar sobrecompacción o subcompactación. (Estandar) BOMAG TERRAMETER Sistema que mide la rigidez del suelo mediante la vibración del tambor. Ofrece una lectura en tiempo real del módulo de elasticidad del material compactado, lo que facilita el control preciso de la compactación y la trazabilidad de los trabajos. Evib - MN/m2 | N9: Telematics | O9: Economizer, TERRAMETER (Evib real), VARIOCONTROL, ECOMODE, TELEMATIC | Q9: Operación Intuitiva * Un switch para cada función * Símbolos intuitivos facilitan la operación | R9: Rendimiento de compactación más alto * Máximas amplitudes para un efecto de compactación más profundo (Larger amplitud 2,2 mm) * Flexibilidad en el montaje del kit pata de cabra | S9: Junta de articulación libre de mantenimiento | T9: Trabajo comfortable y seguro * Espacio de trabajo amplio y con excelente visibilidad | U9: Compactación eficiente Medición y documentación en tiempo real usando: ECONOMIZER, TERRAMETER y BOMAP | V9: Fácil mantenimiento * Todos los componentes dispuestos para un fácil acceso * Menos mantenimiento en el sistema de refrigeración debido al el punto alto de entrada de aire, menos propenso a contaminación | X9: - | Y9: 0 | Z9: 0 | AA9: 1 | AB9: 2 | AC9: 3000 | AD9: 0
A10: =B10&" | "&C10 -> BOMAG | BW219 D-5 PL | B10: BOMAG | C10: BW219 D-5 PL | E10: 19400 | F10: Deutz TCD 2012 L06 | G10: 2.13 | H10: 202 | I10: 2.10 / 1.20 | J10: 60.1 | L10: - | M10: BOMAG ECONOMIZER Sistema visual que permite a los operadores medir el progreso de la compactación en tiempo real. Utiliza una escala LED en la cabina para mostrar el nivel de compactación alcanzado, ayudando a evitar sobrecompacción o subcompactación. (Estandar) BOMAG TERRAMETER Sistema que mide la rigidez del suelo mediante la vibración del tambor. Ofrece una lectura en tiempo real del módulo de elasticidad del material compactado, lo que facilita el control preciso de la compactación y la trazabilidad de los trabajos. Evib - MN/m2 | N10: Telematics | O10: Economizer, TERRAMETER (Evib real), VARIOCONTROL, ECOMODE, TELEMATIC | Q10: Operación Intuitiva * Un switch para cada función * Símbolos intuitivos facilitan la operación | R10: Rendimiento de compactación más alto * Máximas amplitudes para un efecto de compactación más profundo (Larger amplitud 2,2 mm) * Flexibilidad en el montaje del kit pata de cabra | S10: Junta de articulación libre de mantenimiento | T10: Trabajo comfortable y seguro * Espacio de trabajo amplio y con excelente visibilidad | U10: Compactación eficiente Medición y documentación en tiempo real usando: ECONOMIZER, TERRAMETER y BOMAP | V10: Fácil mantenimiento * Todos los componentes dispuestos para un fácil acceso * Menos mantenimiento en el sistema de refrigeración debido al el punto alto de entrada de aire, menos propenso a contaminación | X10: - | Y10: 0 | Z10: 0 | AA10: 1 | AB10: 2 | AC10: 3000 | AD10: 0
A11: =B11&" | "&C11 -> BOMAG | BW220 D-5 PL | B11: BOMAG | C11: BW220 D-5 PL | E11: 20100 | F11: Deutz TCD 2012 L06 | G11: 2.13 | H11: 202 | I11: 2.10 / 1.20 | J11: 61.8 | L11: - | M11: BOMAG ECONOMIZER Sistema visual que permite a los operadores medir el progreso de la compactación en tiempo real. Utiliza una escala LED en la cabina para mostrar el nivel de compactación alcanzado, ayudando a evitar sobrecompacción o subcompactación. (Estandar) BOMAG TERRAMETER Sistema que mide la rigidez del suelo mediante la vibración del tambor. Ofrece una lectura en tiempo real del módulo de elasticidad del material compactado, lo que facilita el control preciso de la compactación y la trazabilidad de los trabajos. Evib - MN/m2 | N11: Telematics | O11: Economizer, TERRAMETER (Evib real), VARIOCONTROL, ECOMODE, TELEMATIC | Q11: Operación Intuitiva * Un switch para cada función * Símbolos intuitivos facilitan la operación | R11: Rendimiento de compactación más alto * Máximas amplitudes para un efecto de compactación más profundo (Larger amplitud 2,2 mm) * Flexibilidad en el montaje del kit pata de cabra | S11: Junta de articulación libre de mantenimiento | T11: Trabajo comfortable y seguro * Espacio de trabajo amplio y con excelente visibilidad | U11: Compactación eficiente Medición y documentación en tiempo real usando: ECONOMIZER, TERRAMETER y BOMAP | V11: Fácil mantenimiento * Todos los componentes dispuestos para un fácil acceso * Menos mantenimiento en el sistema de refrigeración debido al el punto alto de entrada de aire, menos propenso a contaminación | X11: - | Y11: 0 | Z11: 0 | AA11: 1 | AB11: 2 | AC11: 3000 | AD11: 0
A12: =B12&" | "&C12 -> SAKAI | SV521D | B12: SAKAI | C12: SV521D | E12: 10720 | F12: ISUZU 4BG1T (Tier 2) | G12: 2.3 | H12: 118 | I12: 2.05/0.90 | J12: 28 | L12: - | M12: No aplica | N12: - | Q12: Especificaciones técnicas * Motor ISUZU 4BG1T (Tier 2) * 118 HP * Peso operativo 10,720 kg | R12: Rendimiento de compactación * Amplitud 2.05/0.90 mm * Fuerza centrífuga 260/ kN * Carga lineal estática 28 kg/cm | X12: - | Y12: 0 | Z12: 0 | AA12: 1 | AB12: 2 | AC12: 3000 | AD12: 0
A13: =B13&" | "&C13 -> SAKAI | SV621D | B13: SAKAI | C13: SV621D | E13: 13020 | F13: ISUZU 4BG1T (Tier 2) | G13: 2.3 | H13: 131 | I13: 2.03/0.90 | J13: 34 | L13: - | M13: No aplica | N13: - | Q13: Especificaciones técnicas * Motor ISUZU 4BG1T (Tier 2) * 131 HP * Peso operativo 13,020 kg | R13: Rendimiento de compactación * Amplitud 2.03/0.90 mm * Fuerza centrífuga 260/ kN * Carga lineal estática 34 kg/cm | X13: - | Y13: 0 | Z13: 0 | AA13: 1 | AB13: 2 | AC13: 3000 | AD13: 0
A14: =B14&" | "&C14 -> SAKAI | SV700D | B14: SAKAI | C14: SV700D | E14: 14950 | F14: ISUZU BB-6BG1TRJ | G14: 2.13 | H14: 217 | I14: 2.0 / 0.9 | J14: 39.9 | L14: India | M14: No aplica | N14: - | Q14: Especificaciones técnicas * Motor ISUZU BB-6BG1TRJ * 217 HP * Peso operativo 14,950 kg | R14: Rendimiento de compactación * Amplitud 2.0 / 0.9 mm * Fuerza centrífuga 275 / 220 kN * Carga lineal estática 39.9 kg/cm | X14: - | Y14: 0 | Z14: 0 | AA14: 1 | AB14: 2 | AC14: 3000 | AD14: 0
A15: =B15&" | "&C15 -> SAKAI | SV900-1 | B15: SAKAI | C15: SV900-1 | E15: 19350 | F15: ISUZU AH-4HK1XYLB-01 | G15: 2.13 | H15: 166 | I15: 1.9 / 1.0 | J15: 51.4 | L15: - | M15: No aplica | N15: - | Q15: Especificaciones técnicas * Motor ISUZU AH-4HK1XYLB-01 * 166 HP * Peso operativo 19,350 kg | R15: Rendimiento de compactación * Amplitud 1.9 / 1.0 mm * Fuerza centrífuga 343 / 245 kN * Carga lineal estática 51.4 kg/cm | X15: - | Y15: 0 | Z15: 0 | AA15: 1 | AB15: 2 | AC15: 3000 | AD15: 0
A16: =B16&" | "&C16 -> DYNAPAC | CA25 D-Rhino | B16: DYNAPAC | C16: CA25 D-Rhino | E16: 10400 | F16: Cummins QSF3.8 (T3) | G16: 2.13 | H16: 130 | I16: 1.8/0.9 | J16: 51.4 | K16: 41 | L16: Suecia/Brasil | M16: No aplica Dynapac Compaction Meter (DCM) utiliza un sensor acelerómetro montado en el tambor del compactador, que mide las vibraciones generadas durante la operación. Estas señales se procesan y se presentan como CMV Cuando el CMV deja de aumentar, se considera que se ha alcanzado la compactación | N16: Dyn@lizer | O16: Dynapac Compaction meter (DCM), Dyn@lyzer | Q16: Controles intuitivos: Palancas simples y panel de instrumentos con indicadores claros, fáciles de operar incluso por personal con poca experiencia. | R16: Compactación efectiva * Gracias a su peso operativo y potencia, logra una compactación eficiente en menos pasadas. * Amplitud dual: Permite seleccionar entre alta y baja amplitud para distintos materiales (granulares vs cohesivos), optimizando el rendimiento. | S16: Junta de articulación Ofrece un radio de giro estrecho y seguimiento preciso del terreno. | T16: Control y confort de operación * Ofrece visibilidad total del tambor y área de trabajo. El DCM utiliza un sensor acelerómetro montado en el tambor del compactador, que mide las vibraciones generadas durante la operación | V16: Mantenimiento y Servicio Diseño de fácil acceso: El capó del motor se abre completamente, permitiendo un acceso rápido a los puntos de mantenimiento diario (filtros, niveles, correas). | W16: 55 | X16: 220 - 350 | Y16: 13.6 | Z16: 90000 | AA16: 1 | AB16: 2 | AC16: 3000 | AD16: 160200
A17: =B17&" | "&C17 -> DYNAPAC | CA35 D-Rhino | B17: DYNAPAC | C17: CA35 D-Rhino | E17: 12200 | F17: Cummins QSF3.8 | G17: 2.13 | H17: 130 | I17: 1.7/0.8 | J17: 35 | K17: 46 | L17: Suecia/Brasil | M17: No aplica Dynapac Compaction Meter (DCM) utiliza un sensor acelerómetro montado en el tambor del compactador, que mide las vibraciones generadas durante la operación. Estas señales se procesan y se presentan como CMV Cuando el CMV deja de aumentar, se considera que se ha alcanzado la compactación | N17: Dyn@lizer | O17: Dynapac Compaction meter (DCM), Dyn@lyzer | Q17: Controles intuitivos: Palancas simples y panel de instrumentos con indicadores claros, fáciles de operar incluso por personal con poca experiencia. | R17: Compactación efectiva * Gracias a su peso operativo y potencia, logra una compactación eficiente en menos pasadas. * Amplitud dual: Permite seleccionar entre alta y baja amplitud para distintos materiales (granulares vs cohesivos), optimizando el rendimiento. | S17: Junta de articulación Ofrece un radio de giro estrecho y seguimiento preciso del terreno. | T17: Control y confort de operación * Ofrece visibilidad total del tambor y área de trabajo. El DCM utiliza un sensor acelerómetro montado en el tambor del compactador, que mide las vibraciones generadas durante la operación | V17: Mantenimiento y Servicio Diseño de fácil acceso: El capó del motor se abre completamente, permitiendo un acceso rápido a los puntos de mantenimiento diario (filtros, niveles, correas). | W17: 55 | X17: 220 - 350 | Y17: 13.6 | Z17: 90000 | AA17: 1 | AB17: 2 | AC17: 3000 | AD17: 160200
A18: =B18&" | "&C18 -> DYNAPAC | CA2500D | B18: DYNAPAC | C18: CA2500D | E18: 10000 | F18: Cummins QSB4.5 | G18: 2.13 | H18: 130 | I18: 1.80/0.90 | J18: 26 | L18: - | M18: No aplica | N18: - | Q18: Especificaciones técnicas * Motor Cummins QSB4.5 * 130 HP * Peso operativo 10,000 kg | R18: Rendimiento de compactación * Amplitud 1.80/0.90 mm * Fuerza centrífuga 205/100 kN * Carga lineal estática 26 kg/cm | X18: - | Y18: 0 | Z18: 0 | AA18: 1 | AB18: 2 | AC18: 3000 | AD18: 0
A19: =B19&" | "&C19 -> DYNAPAC | CA3500D | B19: DYNAPAC | C19: CA3500D | E19: 16000 | F19: Cummins QSB6.7 | G19: 2.13 | H19: 174 | I19: 2.00/0.95 | J19: 37.5 | K19: 46 | L19: Suecia/Brasil | M19: No aplica Dynapac Compaction Meter (DCM) utiliza un sensor acelerómetro montado en el tambor del compactador, que mide las vibraciones generadas durante la operación. Estas señales se procesan y se presentan como CMV Cuando el CMV deja de aumentar, se considera que se ha alcanzado la compactación | N19: Dyn@lizer | O19: Dynapac Compaction meter (DCM), Dyn@lyzer | Q19: Controles intuitivos: Palancas simples y panel de instrumentos con indicadores claros, fáciles de operar incluso por personal con poca experiencia. | R19: Compactación efectiva * Gracias a su peso operativo y potencia, logra una compactación eficiente en menos pasadas. * Amplitud dual: Permite seleccionar entre alta y baja amplitud para distintos materiales (granulares vs cohesivos), optimizando el rendimiento. | S19: Junta de articulación Ofrece un radio de giro estrecho y seguimiento preciso del terreno. | T19: Control y confort de operación * Ofrece visibilidad total del tambor y área de trabajo. El DCM utiliza un sensor acelerómetro montado en el tambor del compactador, que mide las vibraciones generadas durante la operación | V19: Mantenimiento y Servicio Diseño de fácil acceso: El capó del motor se abre completamente, permitiendo un acceso rápido a los puntos de mantenimiento diario (filtros, niveles, correas). | W19: 55 | X19: 220 - 350 | Y19: 13.6 | Z19: 90000 | AA19: 1 | AB19: 2 | AC19: 3000 | AD19: 160200
A20: =B20&" | "&C20 -> DYNAPAC | CA4500D | B20: DYNAPAC | C20: CA4500D | E20: 21000 | F20: Cummins QSC8.3 | G20: 2.13 | H20: 250 | I20: 2.10/1.05 | J20: 49.3 | L20: - | M20: No aplica | N20: - | Q20: Especificaciones técnicas * Motor Cummins QSC8.3 * 250 HP * Peso operativo 21,000 kg | R20: Rendimiento de compactación * Amplitud 2.10/1.05 mm * Fuerza centrífuga 340/170 kN * Carga lineal estática 49.3 kg/cm | X20: - | Y20: 0 | Z20: 0 | AA20: 1 | AB20: 2 | AC20: 3000 | AD20: 0
A21: =B21&" | "&C21 -> DYNAPAC REDLINE | DRS120D | B21: DYNAPAC REDLINE | C21: DRS120D | E21: 11400 | F21: Dynapac 4-cyl turbo | G21: 2.13 | H21: 105 | I21: - | J21: 32 | L21: India | M21: No aplica | N21: - | Q21: Especificaciones técnicas * Motor Dynapac 4-cyl turbo * 105 HP * Peso operativo 11,400 kg | R21: Rendimiento de compactación * Carga lineal estática 32 kg/cm | X21: - | Y21: 0 | Z21: 0 | AA21: 1 | AB21: 2 | AC21: 3000 | AD21: 0
A22: =B22&" | "&C22 -> HAMM | HC110 | B22: HAMM | C22: HC110 | E22: 11765 | F22: JDPS 4045PTE | G22: 2.14 | H22: 135.4 | I22: 1.95/0.85 | J22: 29.81 | K22: 58 | L22: Alemania | M22: No aplica HAMM SmartCompaction Value (Solo si es Serie VA) El sistema determina el valor de capacidad de carga actual SCV (Smart Compaction Value) del suelo en MN/m². A continuación, el asistente de compactación coloca automáticamente el sistema de desequilibrio en el tambor VA especialmente desarrollado en todas las situaciones, de modo que siempre oscile con la amplitud óptima | N22: Smart Doc | O22: EcoStop, SmartCompaction, vibración adaptativa | Q22: Conducción y maniobrabilidad * Bloqueo integrado de la articulación pendular * Control de tracción para una óptima transmisión de potencia | R22: Calidad de compactación * Asistente Smart Compact para el ajuste automático de la potencia de compactación *Alta carga lineal y fuerza centrífuga | S22: Articulación pendular de 3 puntos para una estabilidad direccional superior | T22: Control y confort * Gran espacio y comodidad de uso * Condiciones de trabajo ergonómicamente optimizadas gracias a su concepto operativo Easy Drive | U22: Sistema de asistencia de compactación Interfaces digitales * John Deere Operations CenterTM * Track Assist & WPT Compacting * Smart Compact | V22: Mantenimiento eficiente Todos los puntos de mantenimiento, la refrigeración de aceite y de agua y la batería son cómodamente accesibles y están concentrados en un lado de la máquina | W22: 60 | X22: 250 - 400 | Y22: 13.6 | Z22: 91845.1 | AA22: 1 | AB22: 2 | AC22: 3000 | AD22: 149805.1
A23: =B23&" | "&C23 -> HAMM | HC119 | B23: HAMM | C23: HC119 | E23: 11745 | F23: Cummins QSB4.5 | G23: 2.14 | H23: 121 | I23: 1.90/0.90 | J23: 29.1 | K23: 58 | L23: Alemania | M23: No aplica HAMM SmartCompaction Value (Solo si es Serie VA) El sistema determina el valor de capacidad de carga actual SCV (Smart Compaction Value) del suelo en MN/m². A continuación, el asistente de compactación coloca automáticamente el sistema de desequilibrio en el tambor VA especialmente desarrollado en todas las situaciones, de modo que siempre oscile con la amplitud óptima | N23: Smart Doc | O23: EcoStop, SmartCompaction, vibración adaptativa | Q23: Conducción y maniobrabilidad * Bloqueo integrado de la articulación pendular * Control de tracción para una óptima transmisión de potencia | R23: Calidad de compactación * Asistente Smart Compact para el ajuste automático de la potencia de compactación *Alta carga lineal y fuerza centrífuga | S23: Articulación pendular de 3 puntos para una estabilidad direccional superior | T23: Control y confort * Gran espacio y comodidad de uso * Condiciones de trabajo ergonómicamente optimizadas gracias a su concepto operativo Easy Drive | U23: Sistema de asistencia de compactación Interfaces digitales * John Deere Operations CenterTM * Track Assist & WPT Compacting * Smart Compact | V23: Mantenimiento eficiente Todos los puntos de mantenimiento, la refrigeración de aceite y de agua y la batería son cómodamente accesibles y están concentrados en un lado de la máquina | W23: 60 | X23: 250 - 400 | Y23: 13.6 | Z23: 91845.1 | AA23: 1 | AB23: 2 | AC23: 3000 | AD23: 149805.1
A24: =B24&" | "&C24 -> HAMM | H13i | B24: HAMM | C24: H13i | E24: 12600 | F24: Deutz TCD2012 | G24: 2.13 | H24: 130 | I24: 1.90/0.80 | J24: 29.6 | L24: - | M24: No aplica | N24: - | Q24: Especificaciones técnicas * Motor Deutz TCD2012 * 130 HP * Peso operativo 12,600 kg | R24: Rendimiento de compactación * Amplitud 1.90/0.80 mm * Fuerza centrífuga 213/90 kN * Carga lineal estática 29.6 kg/cm | X24: - | Y24: 0 | Z24: 0 | AA24: 1 | AB24: 2 | AC24: 3000 | AD24: 0
A25: =B25&" | "&C25 -> HAMM | H16i | B25: HAMM | C25: H16i | E25: 16430 | F25: Deutz TCD3.6 L6 | G25: 2.14 | H25: 168 | I25: 2.13/0.95 | J25: 38.4 | L25: India | M25: No aplica | N25: - | Q25: Especificaciones técnicas * Motor Deutz TCD3.6 L6 * 168 HP * Peso operativo 16,430 kg | R25: Rendimiento de compactación * Amplitud 2.13/0.95 mm * Fuerza centrífuga 328/150 kN * Carga lineal estática 38.4 kg/cm | X25: - | Y25: 0 | Z25: 0 | AA25: 1 | AB25: 2 | AC25: 3000 | AD25: 0
A26: =B26&" | "&C26 -> HAMM | H18i | B26: HAMM | C26: H18i | E26: 18000 | F26: Deutz TCD3.6 | G26: 2.14 | H26: 215 | I26: 2.10/0.90 | J26: 42.1 | L26: India | M26: No aplica | N26: - | Q26: Especificaciones técnicas * Motor Deutz TCD3.6 * 215 HP * Peso operativo 18,000 kg | R26: Rendimiento de compactación * Amplitud 2.10/0.90 mm * Fuerza centrífuga 354/160 kN * Carga lineal estática 42.1 kg/cm | X26: - | Y26: 0 | Z26: 0 | AA26: 1 | AB26: 2 | AC26: 3000 | AD26: 0
A27: =B27&" | "&C27 -> HAMM | H25i | B27: HAMM | C27: H25i | E27: 24925 | F27: Liebherr D946 | G27: 2.14 | H27: 215 | I27: 2.00/0.90 | J27: 58.3 | L27: - | M27: No aplica | N27: - | Q27: Especificaciones técnicas * Motor Liebherr D946 * 215 HP * Peso operativo 24,925 kg | R27: Rendimiento de compactación * Amplitud 2.00/0.90 mm * Fuerza centrífuga 380/190 kN * Carga lineal estática 58.3 kg/cm | X27: - | Y27: 0 | Z27: 0 | AA27: 1 | AB27: 2 | AC27: 3000 | AD27: 0
A28: =B28&" | "&C28 -> CATERPILLAR | CS10GC | B28: CATERPILLAR | C28: CS10GC | E28: 10492 | F28: Cat C4.4 | G28: 2.13 | H28: 112.4 | I28: 2.0/1.0 | J28: 27.3 | K28: 55 | L28: China | M28: CAT Machine Drive Power (MDP) Este sistema mide la resistencia del terreno durante la compactación, proporcionando datos en tiempo real sobre la capacidad de trabajo del equipo y las condiciones del suelo. Permite ajustar la intensidad de la compactación para evitar sobrecarga en el motor y mejorar la eficiencia. (Opcional) CAT Compaction Meter Value (CMV) Sistema que mide en tiempo real la rigidez del suelo a medida que el tambor vibrante pasa sobre él. El valor se muestra en la cabina, permitiendo a los operadores monitorear el progreso de la compactación. | N28: Vision Link | O28: MDP, CMV, AccuGrade Compaction, Eco-mode, Vision Link | Q28: Controles ergonómicos y simples: * Palanca de control única para avance, vibración y dirección. * Instrumentación digital fácil de leer. | R28: Mayor carga lineal estática Tambor de alto peso y excelente contacto con el suelo para lograr profundidad efectiva de compactación. | S28: Junta de articulación libre de mantenimiento | T28: Plataforma con asiento ajustable, controles a mano, y excelente visibilidad de 360°. Vibración automática (Auto Vibe): El sistema puede activar/desactivar la vibración de forma automática según la velocidad del rodillo o si está detenido, mejorando el control del proces | U28: * Amplitud más alta del mercado * MDP exclusivo de CAT: Mide la resistencia al avance del tambor como un indicador directo del nivel de compactación (ventaja clave frente a modelos tradicionales). | V28: Mantenimiento y Servicio Diseño orientado a bajo mantenimiento: * Intervalos de mantenimiento extendidos. * Reducción de puntos de lubricación gracias al uso de componentes sellados. | W28: 60 | X28: 200 | Y28: 14.5 | Z28: 105298.85 | AA28: 1 | AB28: 2 | AC28: 3000 | AD28: 179548.85
A29: =B29&" | "&C29 -> CATERPILLAR | CS11GC | B29: CATERPILLAR | C29: CS11GC | E29: 10900 | F29: Cat C4.4 (Tier 3) | G29: 2.13 | H29: 74 | I29: 1.88/0.91 | J29: 25.6 | K29: 55 | L29: China | M29: CAT Machine Drive Power (MDP) Este sistema mide la resistencia del terreno durante la compactación, proporcionando datos en tiempo real sobre la capacidad de trabajo del equipo y las condiciones del suelo. Permite ajustar la intensidad de la compactación para evitar sobrecarga en el motor y mejorar la eficiencia. (Opcional) CAT Compaction Meter Value (CMV) Sistema que mide en tiempo real la rigidez del suelo a medida que el tambor vibrante pasa sobre él. El valor se muestra en la cabina, permitiendo a los operadores monitorear el progreso de la compactación. | N29: Vision Link | O29: CMV, AccuGrade Compaction, Eco-mode, Vision Link | Q29: Controles ergonómicos y simples: * Palanca de control única para avance, vibración y dirección. * Pantalla integranda en palanca de control. * Cambio de velocidad asistida * Instrumentación digital fácil de leer. | R29: Mayor carga lineal estática Tambor de alto peso y excelente contacto con el suelo para lograr profundidad efectiva de compactación. | S29: Junta de articulación libre de mantenimiento | T29: Plataforma con asiento ajustable, controles a mano, y excelente visibilidad de 360°. Vibración automática (Auto Vibe): El sistema puede activar/desactivar la vibración de forma automática según la velocidad del rodillo o si está detenido, mejorando el control del proces | U29: * Amplitud más alta del mercado * MDP exclusivo de CAT: Mide la resistencia al avance del tambor como un indicador directo del nivel de compactación (ventaja clave frente a modelos tradicionales). | V29: Mantenimiento y Servicio Diseño orientado a bajo mantenimiento: * Intervalos de mantenimiento extendidos. * Reducción de puntos de lubricación gracias al uso de componentes sellados. | W29: 60 | X29: 200 | Y29: 14.5 | Z29: 105298.85 | AA29: 1 | AB29: 2 | AC29: 3000 | AD29: 179548.85
A30: =B30&" | "&C30 -> CATERPILLAR | CS12 | B30: CATERPILLAR | C30: CS12 | E30: 11743 | F30: Cat C7.1 | G30: 2.13 | H30: 157.6 | I30: 2.1/0.98 | J30: 29.7 | K30: 57 | L30: China | M30: No aplica CAT Compaction Meter Value (CMV) Sistema que mide en tiempo real la rigidez del suelo a medida que el tambor vibrante pasa sobre él. El valor se muestra en la cabina, permitiendo a los operadores monitorear el progreso de la compactación. | N30: Vision Link | O30: MDP, CMV, AccuGrade Compaction, Eco-mode, Vision Link | Q30: Controles ergonómicos y simples: * Palanca de control única para avance, vibración y dirección. * Instrumentación digital fácil de leer. | R30: Diseñado con un sistema de propulsión de doble bomba, las dos bombas suministran un flujo separado y dedicado al motor de accionamiento del tambor y al motor del eje trasero, lo que garantiza una capacidad de ascenso y tracción excepcionales tanto en avance como en retroceso | S30: Junta de articulación libre de mantenimiento | T30: Plataforma con asiento ajustable, controles a mano, y excelente visibilidad de 360°. Vibración automática (Auto Vibe): El sistema puede activar/desactivar la vibración de forma automática según la velocidad del rodillo o si está detenido, mejorando el control del proces | U30: * Amplitud más alta del mercado | V30: Mantenimiento y Servicio Diseño orientado a bajo mantenimiento: * Intervalos de mantenimiento extendidos. * Reducción de puntos de lubricación gracias al uso de componentes sellados. | W30: 60 | X30: 200 | Y30: 14.5 | Z30: 105298.85 | AA30: 1 | AB30: 2 | AC30: 3000 | AD30: 179548.85
A31: =B31&" | "&C31 -> CATERPILLAR | CS13GC | B31: CATERPILLAR | C31: CS13GC | E31: 12700 | F31: Cat C4.4 (Tier 3) | G31: 2.13 | H31: 100 | I31: 2.10/1.05 | J31: 30 | L31: India | M31: No aplica | N31: - | Q31: Especificaciones técnicas * Motor Cat C4.4 (Tier 3) * 100 HP * Peso operativo 12,700 kg | R31: Rendimiento de compactación * Amplitud 2.10/1.05 mm * Fuerza centrífuga 208/100 kN * Carga lineal estática 30 kg/cm | X31: - | Y31: 0 | Z31: 0 | AA31: 1 | AB31: 2 | AC31: 3000 | AD31: 0
A32: =B32&" | "&C32 -> XCMG | XS113E | B32: XCMG | C32: XS113E | E32: 10400 | F32: Weichai WP4 | G32: 2.13 | H32: 110 | I32: 1.80/0.90 | J32: 0 | K32: 45 | L32: Brasil | M32: No aplica No aplica | N32: - | O32: XCMG Telematics | Q32: Diseño robusto, excelente acceso a mantenimiento y componentes estandarizados para máxima disponibilidad en campo. | R32: Calidad de Compactación * Rendimiento adecuado para compactación de capas gruesas y materiales cohesivos. * Diseño del tambor que reduce rebotes y mejora la uniformidad. | S32: Junta de Articulación Articulación oscilante de diseño robusto. | T32: Control y Confort * Cabina opcional con buena visibilidad. * Panel de instrumentos digital con indicadores de trabajo. * Asiento ajustable, pero menor confort que modelos premium. | U32: - | V32: Mantenimiento y Servicio Capó lateral basculante, acceso rápido a motor y componentes hidráulicos. Módulos eléctricos centralizados. Motores Weichai o Cummins con buena cobertura de repuestos. | W32: 50 | X32: 250 - 400 | Y32: 13.6 | Z32: 54786 | AA32: 1 | AB32: 2 | AC32: 3000 | AD32: 124986
A33: =B33&" | "&C33 -> XCMG | XS123 | B33: XCMG | C33: XS123 | E33: 12000 | F33: Cummins QSF3.8 | G33: 2.13 | H33: 139 | I33: 1.8/0.9 | J33: 31.5 | K33: 45 | L33: Brasil | M33: No aplica No aplica | N33: - | O33: XCMG Telematics | Q33: Diseño robusto, excelente acceso a mantenimiento y componentes estandarizados para máxima disponibilidad en campo. | R33: Calidad de Compactación * Rendimiento adecuado para compactación de capas gruesas y materiales cohesivos. * Diseño del tambor que reduce rebotes y mejora la uniformidad. | S33: Junta de Articulación Articulación oscilante de diseño robusto. | T33: Control y Confort * Cabina opcional con buena visibilidad. * Panel de instrumentos digital con indicadores de trabajo. * Asiento ajustable, pero menor confort que modelos premium. | U33: - | V33: Mantenimiento y Servicio Capó lateral basculante, acceso rápido a motor y componentes hidráulicos. Módulos eléctricos centralizados. Motores Weichai o Cummins con buena cobertura de repuestos. | W33: 50 | X33: 250 - 400 | Y33: 13.6 | Z33: 54786 | AA33: 1 | AB33: 2 | AC33: 3000 | AD33: 124986
A34: =B34&" | "&C34 -> XCMG | XS143J | B34: XCMG | C34: XS143J | E34: 14000 | F34: Cummins B5.9 | G34: 2.13 | H34: 150 | I34: 1.90/0.95 | J34: 0 | L34: India | M34: No aplica | N34: - | Q34: Especificaciones técnicas * Motor Cummins B5.9 * 150 HP * Peso operativo 14,000 kg | R34: Rendimiento de compactación * Amplitud 1.90/0.95 mm * Fuerza centrífuga 230/115 kN | X34: - | Y34: 0 | Z34: 0 | AA34: 1 | AB34: 2 | AC34: 3000 | AD34: 0
A35: =B35&" | "&C35 -> XCMG | XS162J | B35: XCMG | C35: XS162J | E35: 16000 | F35: Cummins B5.9 | G35: 2.13 | H35: 161 | I35: 2.00/0.95 | J35: 0 | L35: - | M35: No aplica | N35: - | Q35: Especificaciones técnicas * Motor Cummins B5.9 * 161 HP * Peso operativo 16,000 kg | R35: Rendimiento de compactación * Amplitud 2.00/0.95 mm * Fuerza centrífuga 260/130 kN | X35: - | Y35: 0 | Z35: 0 | AA35: 1 | AB35: 2 | AC35: 3000 | AD35: 0
A36: =B36&" | "&C36 -> XCMG | XS182 | B36: XCMG | C36: XS182 | E36: 18000 | F36: Cummins B5.9 | G36: 2.13 | H36: 174 | I36: 1.86/ | J36: 53.9 | L36: - | M36: No aplica | N36: - | Q36: Especificaciones técnicas * Motor Cummins B5.9 * 174 HP * Peso operativo 18,000 kg | R36: Rendimiento de compactación * Amplitud 1.86/ mm * Carga lineal estática 53.9 kg/cm | X36: - | Y36: 0 | Z36: 0 | AA36: 1 | AB36: 2 | AC36: 3000 | AD36: 0
A37: =B37&" | "&C37 -> XCMG | XS203J | B37: XCMG | C37: XS203J | E37: 20000 | F37: Cummins QSB6.7 | G37: 2.13 | H37: 200 | I37: 2.00/1.00 | J37: 0 | L37: - | M37: No aplica | N37: - | Q37: Especificaciones técnicas * Motor Cummins QSB6.7 * 200 HP * Peso operativo 20,000 kg | R37: Rendimiento de compactación * Amplitud 2.00/1.00 mm * Fuerza centrífuga 310/155 kN | X37: - | Y37: 0 | Z37: 0 | AA37: 1 | AB37: 2 | AC37: 3000 | AD37: 0
A38: =B38&" | "&C38 -> SANY | SSR120C-8 | B38: SANY | C38: SSR120C-8 | E38: 11580 | F38: Cummins QSB4.5 | G38: 2.13 | H38: 145 | I38: 1.80/0.90 | J38: 0 | L38: India | M38: No aplica | N38: - | Q38: Especificaciones técnicas * Motor Cummins QSB4.5 * 145 HP * Peso operativo 11,580 kg | R38: Rendimiento de compactación * Amplitud 1.80/0.90 mm * Fuerza centrífuga 190/95 kN | X38: - | Y38: 0 | Z38: 0 | AA38: 1 | AB38: 2 | AC38: 3000 | AD38: 0
A39: =B39&" | "&C39 -> SANY | SSR120C-10 | B39: SANY | C39: SSR120C-10 | E39: 12000 | F39: ISUZU 4JJ1 | G39: 2.13 | H39: 130 | I39: 1.80/0.90 | J39: 0 | L39: India | M39: No aplica | N39: - | Q39: Especificaciones técnicas * Motor ISUZU 4JJ1 * 130 HP * Peso operativo 12,000 kg | R39: Rendimiento de compactación * Amplitud 1.80/0.90 mm * Fuerza centrífuga 205/100 kN | X39: - | Y39: 0 | Z39: 0 | AA39: 1 | AB39: 2 | AC39: 3000 | AD39: 0
A40: =B40&" | "&C40 -> SANY | SSR120C-10S | B40: SANY | C40: SSR120C-10S | E40: 12400 | F40: DONGFENG CUMMINS QSB3.9-C150-3 | G40: 2.13 | H40: 110 | I40: 1.8/0.9 | J40: 33.2 | K40: 65 | L40: China/Brasil | M40: No aplica No aplica | N40: - | O40: Tracción automática, vibración doble, telematics-ready | Q40: Controles fáciles de usar: * Palanca tipo joystick para dirección, vibración y cambio de marcha. | R40: Calidad de compactación * Fuerza centrífuga hasta 320 kN, una de las más altas del segmento. * Sistema de vibración confiable con buena transferencia de energía. * Distribución de peso balanceada para compactación uniforme. | S40: Articulación con oscilación hidráulica y gran ángulo de giro. | T40: Control y Confort * Cabina cerrada ROPS/FOPS opcional con aire acondicionado y asiento neumático. * Palanca tipo joystick para dirección, vibración y cambio de marcha. * Bajo nivel de vibración transmitida al operador. | U40: Sistema inteligente de control de vibración que ajusta la potencia según la resistencia del suelo, evitando sobrecompactación. | V40: Mantenimiento y Servicio * Capó de apertura total con acceso a 3 lados del motor. * Sistema de diagnóstico electrónico desde la pantalla de control. * Componentes hidráulicos y eléctricos dispuestos para fácil inspección. | W40: 60 | X40: 300 - 500 | Y40: 15.3 | Z40: 56392 | AA40: 1 | AB40: 2 | AC40: 3000 | AD40: 134242
...

Sheet Datos LTR
A1: ID | B1: Marca | C1: Modelo | D1: Peso (kg) | E1: Motor | F1: Ancho de compactación (m) | G1: Potencia (HP) | H1: Amplitud (mm) | I1: Carga lineal estática (kg/cm) | J1: País de origen | K1: Asistente de compactación | L1: Tecnologías innovadoras | M1: USP | N1: Consumo de combustible (L/h) | O1: Precio CIF (USD) | P1: Mant. preventivo (USD/h) | Q1: Mant. correctivo (USD/h) | R1: Tiempo de uso (h) | S1: TCO estático app (USD) | T1: Sistema de compactación | U1: Tanque de agua (L) | V1: Junta de articulación | W1: Confort y seguridad | X1: Compactación eficiente | Y1: Tecnología ACE | Z1: Mantenimiento fácil | AA1: TCO estático (USD) | AB1: Línea de tiempo TCO (datos app)
A2: =B2&" | "&C2 -> BOMAG | BW120 AD-5 | B2: BOMAG | C2: BW120 AD-5 | D2: 2700 | E2: Kubota D1703 | F2: 1.2 | G2: 32.6 | H2: 0.5 | I2: 11.3 | J2: Germany/China | K2: Economizer - Sensor de rigidez del suelo | L2: Bajos TCO (Servicio/Matenimiento/Reparación/confiabilidad) | M2: Fácil y seguro de operar. Economizer (Opción) Incluye indicador de temperatura | N2: 2.6 | O2: 28000 | P2: 1 | Q2: 1.3 | R2: 3500 | S2: 49700 | T2: Vibratory | U2: 205 | V2: Articulación de la rueda | W2: Confort y seguridad | X2: Compactación eficiente | Y2: Tecnología ACE | Z2: Mantenimiento fácil | AA2: 49700 | AB2: 0 h: precio 28000 / TCO 49700; 1000 h: precio 32900 / TCO 49700; 1500 h: precio 35350 / TCO 49700; 2000 h: precio 37800 / TCO 49700; 2500 h: precio 40250 / TCO 49700; 3000 h: precio 42700 / TCO 49700
A3: =B3&" | "&C3 -> CATERPILLAR | CB2.7GC | B3: CATERPILLAR | C3: CB2.7GC | D3: 2698 | E3: CAT C1.7T | F3: 1.3 | G3: 24.6 | H3: 0.52 | I3: 13.7 | J3: China | K3: CMV (Compaction Meter Value) | L3: Rodillo de bajo costo operativo, ideal para flotas de alquiler o trabajos donde la simplicidad y confiabilidad mecánica son prioridad. | M3: Rodillo de bajo costo operativo, ideal para flotas de alquiler o trabajos donde la simplicidad y confiabilidad mecánica son prioridad. | N3: 2.3 | O3: 29630 | P3: 1 | Q3: 2 | R3: 3500 | S3: 52205 | T3: Vibratory | U3: 200 | V3: Articulación de la rueda | W3: Confort y seguridad | X3: Compactación eficiente | Y3: Tecnología ACE | Z3: Mantenimiento fácil | AA3: 52205 | AB3: 0 h: precio 29630 / TCO 52205; 1000 h: precio 34930 / TCO 52205; 1500 h: precio 37580 / TCO 52205; 2000 h: precio 40230 / TCO 52205; 2500 h: precio 42880 / TCO 52205; 3000 h: precio 45530 / TCO 52205
A4: =B4&" | "&C4 -> HAMM | HD12 VV | B4: HAMM | C4: HD12 VV | D4: 2695 | E4: Kubota D1503 | F4: 1.25 | G4: 30.7 | H4: 0.52 | I4: 11.2 | J4: Czech | K4: HAMM Compaction Meter: Sensor de aceleración / frecuencia | L4: Máxima maniobrabilidad con doble tambor vibratorio y opción de configuración para zonas urbanas estrechas | M4: Máxima maniobrabilidad con doble tambor vibratorio y opción de configuración para zonas urbanas estrechas | N4: 2.8 | O4: 29580 | P4: 1.5 | Q4: 1 | R4: 3500 | S4: 53030 | T4: Vibratory | U4: 180 | V4: Articulación de la rueda | W4: Confort y seguridad | X4: Compactación eficiente | Y4: Tecnología ACE | Z4: Mantenimiento fácil | AA4: 53030 | AB4: 0 h: precio 29580 / TCO 53030; 1000 h: precio 34880 / TCO 53030; 1500 h: precio 37480 / TCO 53030; 2000 h: precio 40080 / TCO 53030; 2500 h: precio 42680 / TCO 53030; 3000 h: precio 45280 / TCO 53030
A5: =B5&" | "&C5 -> DYNAPAC | CC1200 | B5: DYNAPAC | C5: CC1200 | D5: 2600 | E5: Kubota D1703-M | F5: 1.2 | G5: 35 | H5: 0.508 | I5: 10.5 | J5: Brasil | K5: DCA-A Sensor de aceleración / amplitud | L5: Chasis compacto con diseño en tándem y opción de sistema DCA para trazabilidad por zonas (en modelos superiores). | M5: Chasis compacto con diseño en tándem y opción de sistema DCA para trazabilidad por zonas (en modelos superiores). | N5: 2.7 | O5: 26783 | P5: 1 | Q5: 1.4 | R5: 3500 | S5: 49358 | T5: Vibratory | U5: 159 | V5: Articulación de la rueda | W5: Confort y seguridad | X5: Compactación eficiente | Y5: Tecnología ACE | Z5: Mantenimiento fácil | AA5: 49358 | AB5: 0 h: precio 26783 / TCO 49358; 1000 h: precio 31783 / TCO 49358; 1500 h: precio 34283 / TCO 49358; 2000 h: precio 36783 / TCO 49358; 2500 h: precio 39283 / TCO 49358; 3000 h: precio 41783 / TCO 49358
A6: =B6&" | "&C6 -> AMMANN | ARX 26 | B6: AMMANN | C6: ARX 26 | D6: 2460 | E6: Yanmar 3TNV88F | F6: 1.2 | G6: 27.3 | H6: 0.6 | I6: 10.3 | J6: Switzerland | K6: ACEforce: Sensor de rigidez dinámica | L6: Tecnología de compactación activa que ajusta automáticamente la vibración según la rigidez del suelo para optimizar el número de pasadas. | M6: Tecnología de compactación activa que ajusta automáticamente la vibración según la rigidez del suelo para optimizar el número de pasadas. | N6: 3.2 | O6: 25500 | P6: 1 | Q6: 1.3 | R6: 3500 | S6: 50350 | T6: Vibratory | U6: 110 | V6: Articulación de la rueda | W6: Confort y seguridad | X6: Compactación eficiente | Y6: Tecnología ACE | Z6: Mantenimiento fácil | AA6: 50350 | AB6: 0 h: precio 25500 / TCO 50350; 1000 h: precio 29500 / TCO 50350; 1500 h: precio 31500 / TCO 50350; 2000 h: precio 33500 / TCO 50350; 2500 h: precio 35500 / TCO 50350; 3000 h: precio 37500 / TCO 50350
A7: =B7&" | "&C7 -> JCB | CT260 | B7: JCB | C7: CT260 | D7: 2740 | E7: Kubota D1703-M | F7: 1.2 | G7: 24.4 | H7: 0.51 | I7: 10.5 | J7: India | K7: No aplica | L7: Diseño robusto, excelente acceso a mantenimiento y componentes estandarizados para máxima disponibilidad en campo. | M7: Diseño robusto, excelente acceso a mantenimiento y componentes estandarizados para máxima disponibilidad en campo. | N7: 2.7 | O7: 23500 | P7: 1.5 | Q7: 2 | R7: 3500 | S7: 49925 | T7: Vibratory | U7: 197 | V7: Articulación de la rueda | W7: Confort y seguridad | X7: Compactación eficiente | Y7: Tecnología ACE | Z7: Mantenimiento fácil | AA7: 49925 | AB7: 0 h: precio 23500 / TCO 49925; 1000 h: precio 27500 / TCO 49925; 1500 h: precio 29500 / TCO 49925; 2000 h: precio 31500 / TCO 49925; 2500 h: precio 33500 / TCO 49925; 3000 h: precio 35500 / TCO 49925
A8: =B8&" | "&C8 -> WACKER NEUSON | RD27 | B8: WACKER NEUSON | C8: RD27 | D8: 2695 | E8: Kubota D1903-M | F8: 1.2 | G8: 30.7 | H8: 0.51 | I8: 10.5 | J8: Germany | K8: No aplica | L8: Diseño robusto, excelente acceso a mantenimiento y componentes estandarizados para máxima disponibilidad en campo. | M8: Diseño robusto, excelente acceso a mantenimiento y componentes estandarizados para máxima disponibilidad en campo. | N8: 2.7 | O8: 23500 | P8: 1.5 | Q8: 2 | R8: 3500 | S8: 49925 | T8: Vibratory | U8: 197 | V8: Articulación de la rueda | W8: Confort y seguridad | X8: Compactación eficiente | Y8: Tecnología ACE | Z8: Mantenimiento fácil | AA8: 49925 | AB8: 0 h: precio 23500 / TCO 49925; 1000 h: precio 27500 / TCO 49925; 1500 h: precio 29500 / TCO 49925; 2000 h: precio 31500 / TCO 49925; 2500 h: precio 33500 / TCO 49925; 3000 h: precio 35500 / TCO 49925

Sheet Datos HTR
A1: ID | B1: Marca | C1: Modelo | D1: Peso (kg) | E1: Motor | F1: Ancho de compactación (m) | G1: Potencia (HP) | H1: Amplitud (mm) | I1: Carga lineal estática (kg/cm) | J1: Gradeabilidad (%) | K1: País de origen | L1: Asistente de compactación | M1: Asphalt Manager | N1: Telemetría | O1: Tecnologías innovadoras | P1: Sistemas de vibración / notas | Q1: Junta de articulación libre de mantenimiento | R1: Consumo de combustible (L/h) | S1: Precio CIF (USD) | T1: Mant. preventivo (USD/h) | U1: Mant. correctivo (USD/h) | V1: Tiempo de uso (h) | W1: TCO estático app (USD) | X1: USP | Y1: Profundidad de compactación máx. | Z1: Rendimiento en compactación (m³/h, ficha) | AA1: Línea de tiempo TCO (datos app)
A2: =B2&" | "&C2 -> BOMAG | BW161 AD-4 | B2: BOMAG | C2: BW161 AD-4 | D2: 9700 | E2: Deutz TCD L04 2V | F2: 1.68 | G2: 114 | H2: 0,94/0,42 | I2: 30.1 | J2: 35 | K2: Alemania | L2: BOMAG ECONOMIZER Sistema visual que permite a los operadores medir el progreso de la compactación en tiempo real. Utiliza una escala LED en la cabina para mostrar el nivel de compactación alcanzado, ayudando a evitar sobrecompacción o subcompactación. | M2: BOMAG ASPHALT MANAGER Ningún otro sistema es tan flexible como la AM: con la amplitud de salida variable, puede ser potente o sensible. Se aplica el nivel de fuerza adecuado en la dirección correcta en cualquier aplicación: Adaptación del tambor de vibración hasta oscilación. Medición del Evib en MN/m2 | N2: Telematic, BOMAP | O2: TANGO, ASPHALT MANAGER, ECONOMIZER ECOMODE, TELEMATIC | P2: 3 sistemas de vibración Solo los rodillos tándem BOMAG le ofrecen tres sistemas de vibración. Con doble vibración, TanGO y ASPHALT MANAGER, tiene tres tecnologías para elegir. | Q2: Junta de articulación libre de mantenimiento | R2: 11.8 | S2: 28000 | T2: 1 | U2: 2 | V2: 2000 | W2: 50000 | X2: TANGO, ASPHALT MANAGER, ECONOMIZER ECOMODE, TELEMATIC | Y2: 0.3 | Z2: 150-200 | AA2: 0 h: precio 28000 / TCO 28000; 1000 h: precio - / TCO 35000; 2000 h: precio - / TCO 42000
A3: =B3&" | "&C3 -> AMMANN | AV110X | B3: AMMANN | C3: AV110X | D3: 10400 | E3: Cummins QSB3.3-C99 | F3: 1.7 | G3: 99 | H3: 0,7/0,35 | I3: 30.9 | J3: 30 | K3: República Checa | L3: No aplica | M3: No aplica | N3: Dyn@Link | O3: Junta con oscilación, diagnóstico abordo | P3: Alta visibilidad, compactación potente y cómoda | Q3: No aplica | R3: 11.8 | S3: 28000 | T3: 1 | U3: 2 | V3: 2000 | W3: 50000 | X3: Junta con oscilación, diagnóstico abordo | Y3: 0.3 | Z3: 140-180 | AA3: 0 h: precio 28000 / TCO 28000; 1000 h: precio - / TCO 35000; 2000 h: precio - / TCO 42000
